Workbook

Sheet Summary
A1: CoreWeave, Inc. (CRWV) — Investment Summary
A2: US GAAP | Units: $M | NASDAQ: CRWV | Sector: Cloud Infrastructure / GPU-as-a-Service
A4: 1. BUSINESS PROFILE & INVESTMENT THESIS
A5: Core Business: Purpose-built GPU cloud infrastructure provider (Neocloud). Operates 28 data centers across NA/EU with ~600K GPUs.
A6: Revenue Model: Take-or-pay contracts with hyperscalers (Microsoft ~62% of FY2025 rev), AI labs, and enterprises. Multi-year committed arrangements with 3-5yr weighted avg contract life.
A7: Key Assets: NVIDIA H100/H200/GB200 GPU fleet, proprietary Kubernetes orchestration (CoreWeave Cloud OS), 850MW+ active power capacity.
A8: Moat: (1) First-mover GPU cloud scale; (2) Deep NVIDIA partnership (preferred partner status); (3) Purpose-built infra vs retrofitted hyperscaler; (4) Take-or-pay revenue visibility ($60.7B RPO, $87.8B backlog).
A10: INVESTMENT THESIS — Asymmetric Risk-Reward; Wait for Catalyst
A11: Core View: CoreWeave is a high-quality GPU infrastructure franchise with $88B backlog and 60% EBITDA margin — but the market is pricing this correctly at $118. Probability-weighted target ~$139 (+17% upside) against 35% Bear+Distress probability (-60% to -100%). This is a 3-year growth trade, not a long-term hold: moat decays from 4/5 to 2/5 over 5 years as GPU scarcity fades, contracts reprice, and inference switching costs stay low.
A12: What Must Go Right: (1) Revenue visibility — $60.7B RPO locks ~$13B/yr through 2027, but 2030+ drops to ~$3.3B/yr without $20-25B/yr new backlog; (2) EBITDA scales from $3.1B to $7-11B (FY26-27E) enabling deleverage from 5.65x to <3.5x; (3) GAAP profitability by FY2027E requires $19-20B revenue — narrow margin of error; (4) FCF turns positive by FY2028-29 as capex decelerates from $20B to $10B.
A13: What Can Go Wrong: (1) Customer concentration — MSFT 67% of revenue, top-3 = 77-89% of backlog; systemic retrenchment is existential; (2) GPU oversupply 2027-28 — TSMC CoWoS doubling + $400B+ hyperscaler capex + 4 custom silicon programs converge; H100 pricing already crashed 64%; (3) Leverage — 5.65x net leverage with 0.35x covenant headroom; FY2026 H2 still needs $8-12B funding; CDS 665bps implies 42% 5yr default probability.
A14: Decision Framework: Q1 FY2026 margin recovery (May earnings) = increase position. Q1 margin miss = reduce. Covenant headroom <0.15x = exit immediately. Position sizing: 3-5% for high-risk growth, 1-2% balanced, 0-0.5% conservative. Capital-intensive D&A-heavy model caps mature valuation at AerCap 6-8x (not Equinix 20x).
... A17: 2. FINANCIAL HIGHLIGHTS
A18: Metric | B18: FY2023 | C18: FY2024 | D18: FY2025 | E18: FY2026E | F18: FY2027E | G18: FY2028E | H18: FY2029E | I18: FY2030E
A19: Revenue ($M) | B19: =IS!B5 -> 229 | C19: =IS!C5 -> 1915 | D19: =IS!D5 -> 5131 | E19: =IS!E5 -> 12500 | F19: =IS!F5 -> 20000 | G19: =IS!G5 -> 22000 | H19: =IS!H5 -> 24000 | I19: =IS!I5 -> 25000
A20: YoY Growth % | C20: =IF(IS!B5=0,0,IS!C5/IS!B5-1) -> 7.3624454 | D20: =IF(IS!C5=0,0,IS!D5/IS!C5-1) -> 1.6793734 | E20: =IF(IS!D5=0,0,IS!E5/IS!D5-1) -> 1.4361723 | F20: =IF(IS!E5=0,0,IS!F5/IS!E5-1) -> 0.6 | G20: =IF(IS!F5=0,0,IS!G5/IS!F5-1) -> 0.1 | H20: =IF(IS!G5=0,0,IS!H5/IS!G5-1) -> 0.090909091 | I20: =IF(IS!H5=0,0,IS!I5/IS!H5-1) -> 0.041666667
A21: Gross Profit ($M) | B21: =IS!B11 -> 160 | C21: =IS!C11 -> 1422 | D21: =IS!D11 -> 3678 | E21: =IS!E11 -> 8750 | F21: =IS!F11 -> 14000 | G21: =IS!G11 -> 14960 | H21: =IS!H11 -> 16080 | I21: =IS!I11 -> 16500
A22: Gross Margin % | B22: =IF(IS!B5=0,0,IS!B11/IS!B5) -> 0.69868996 | C22: =IF(IS!C5=0,0,IS!C11/IS!C5) -> 0.74255875 | D22: =IF(IS!D5=0,0,IS!D11/IS!D5) -> 0.71681933 | E22: =IF(IS!E5=0,0,IS!E11/IS!E5) -> 0.7 | F22: =IF(IS!F5=0,0,IS!F11/IS!F5) -> 0.7 | G22: =IF(IS!G5=0,0,IS!G11/IS!G5) -> 0.68 | H22: =IF(IS!H5=0,0,IS!H11/IS!H5) -> 0.67 | I22: =IF(IS!I5=0,0,IS!I11/IS!I5) -> 0.66
A23: EBITDA ($M) | B23: =IS!B43 -> 103 | C23: =IS!C43 -> 1218 | D23: =IS!D43 -> 3038 | E23: =IS!E43 -> 7425 | F23: =IS!F43 -> 11700 | G23: =IS!G43 -> 13550 | H23: =IS!H43 -> 14810 | I23: =IS!I43 -> 15350
A24: EBITDA Margin % | B24: =IF(IS!B5=0,0,IS!B43/IS!B5) -> 0.44978166 | C24: =IF(IS!C5=0,0,IS!C43/IS!C5) -> 0.63603133 | D24: =IF(IS!D5=0,0,IS!D43/IS!D5) -> 0.59208731 | E24: =IF(IS!E5=0,0,IS!E43/IS!E5) -> 0.594 | F24: =IF(IS!F5=0,0,IS!F43/IS!F5) -> 0.585 | G24: =IF(IS!G5=0,0,IS!G43/IS!G5) -> 0.61590909 | H24: =IF(IS!H5=0,0,IS!H43/IS!H5) -> 0.61708333 | I24: =IF(IS!I5=0,0,IS!I43/IS!I5) -> 0.614
A25: Operating Income ($M) | B25: =IS!B22 -> -15 | C25: =IS!C22 -> 324 | D25: =IS!D22 -> -46 | E25: =IS!E22 -> 2125 | F25: =IS!F22 -> 5000 | G25: =IS!G22 -> 6050 | H25: =IS!H22 -> 6960 | I25: =IS!I22 -> 7250
A26: Operating Margin % | B26: =IF(IS!B5=0,0,IS!B22/IS!B5) -> -0.065502183 | C26: =IF(IS!C5=0,0,IS!C22/IS!C5) -> 0.1691906 | D26: =IF(IS!D5=0,0,IS!D22/IS!D5) -> -0.008965114 | E26: =IF(IS!E5=0,0,IS!E22/IS!E5) -> 0.17 | F26: =IF(IS!F5=0,0,IS!F22/IS!F5) -> 0.25 | G26: =IF(IS!G5=0,0,IS!G22/IS!G5) -> 0.275 | H26: =IF(IS!H5=0,0,IS!H22/IS!H5) -> 0.29 | I26: =IF(IS!I5=0,0,IS!I22/IS!I5) -> 0.29
A27: Net Income ($M) | B27: =IS!B34 -> -594 | C27: =IS!C34 -> -863 | D27: =IS!D34 -> -1167 | E27: =IS!E34 -> -254.8 | F27: =IS!F34 -> 2118.5 | G27: =IS!G34 -> 3222 | H27: =IS!H34 -> 4071.5 | I27: =IS!I34 -> 4329.6
A28: NI Margin % | B28: =IF(IS!B5=0,0,IS!B34/IS!B5) -> -2.5938865 | C28: =IF(IS!C5=0,0,IS!C34/IS!C5) -> -0.45065274 | D28: =IF(IS!D5=0,0,IS!D34/IS!D5) -> -0.22744104 | E28: =IF(IS!E5=0,0,IS!E34/IS!E5) -> -0.020384 | F28: =IF(IS!F5=0,0,IS!F34/IS!F5) -> 0.105925 | G28: =IF(IS!G5=0,0,IS!G34/IS!G5) -> 0.14645455 | H28: =IF(IS!H5=0,0,IS!H34/IS!H5) -> 0.16964583 | I28: =IF(IS!I5=0,0,IS!I34/IS!I5) -> 0.173184
A29: EPS (Basic) | B29: =IS!B45 -> -1.129922 | C29: =IS!C45 -> -1.6416207 | D29: =IS!D45 -> -2.2198973 | E29: =IS!E45 -> -0.46752294 | F29: =IS!F45 -> 3.7166667 | G29: =IS!G45 -> 5.37 | H29: =IS!H45 -> 6.5669355 | I29: =IS!I45 -> 6.8182677
A31: Total Assets ($M) | B31: N/A | C31: =BS!B18 -> 17833 | D31: =BS!C18 -> 49302 | E31: =BS!D18 -> 71413.077 | F31: =BS!E18 -> 83942.536 | G31: =BS!F18 -> 90506.59 | H31: =BS!G18 -> 94786.584 | I31: =BS!H18 -> 96034.814
A32: Total Debt ($M) | B32: N/A | C32: =BS!B23+BS!B29 -> 7926 | D32: =BS!C23+BS!C29 -> 21373 | E32: =BS!D23+BS!D29 -> 35000 | F32: =BS!E23+BS!E29 -> 35000 | G32: =BS!F23+BS!F29 -> 32500 | H32: =BS!G23+BS!G29 -> 29000 | I32: =BS!H23+BS!H29 -> 25500
A33: Net Debt ($M) | B33: N/A | C33: =BS!B23+BS!B29-BS!B5 -> 6528 | D33: =BS!C23+BS!C29-BS!C5 -> 17393 | E33: =BS!D23+BS!D29-BS!D5 -> 27239.042 | F33: =BS!E23+BS!E29-BS!E5 -> 30092.493 | G33: =BS!F23+BS!F29-BS!F5 -> 29136.805 | H33: =BS!G23+BS!G29-BS!G5 -> 24207.124 | I33: =BS!H23+BS!H29-BS!H5 -> 19457.666
A34: Stockholders' Equity ($M) | B34: N/A | C34: =BS!B42 -> 1308 | D34: =BS!C42 -> 3335 | E34: =BS!D42 -> 6880.2 | F34: =BS!E42 -> 13898.7 | G34: =BS!F42 -> 20120.7 | H34: =BS!G42 -> 26242.2 | I34: =BS!H42 -> 32171.8
A35: Cash & Equivalents ($M) | B35: N/A | C35: =BS!B5 -> 1398 | D35: =BS!C5 -> 3980 | E35: =BS!D5 -> 7760.9578 | F35: =BS!E5 -> 4907.5074 | G35: =BS!F5 -> 3363.1946 | H35: =BS!G5 -> 4792.8759 | I35: =BS!H5 -> 6042.3341
A37: CFO ($M) | B37: =CF!B16 -> 1833 | C37: =CF!C16 -> 2749 | D37: =CF!D16 -> 3058 | E37: =CF!E16 -> 9480.9578 | F37: =CF!F16 -> 3946.5496 | G37: =CF!G16 -> 9355.6872 | H37: =CF!H16 -> 13329.681 | I37: =CF!I16 -> 13649.458
A38: Capex ($M) | B38: =CF!B19 -> -2943 | C38: =CF!C19 -> -8702 | D38: =CF!D19 -> -10309 | E38: =CF!E19 -> -20000 | F38: =CF!F19 -> -18000 | G38: =CF!G19 -> -15000 | H38: =CF!H19 -> -12000 | I38: =CF!I19 -> -10000
A39: FCF ($M) | B39: =CF!B38 -> -1110 | C39: =CF!C38 -> -5953 | D39: =CF!D38 -> -7251 | E39: =CF!E38 -> -10519.042 | F39: =CF!F38 -> -14053.45 | G39: =CF!G38 -> -5644.3128 | H39: =CF!H38 -> 1329.6813 | I39: =CF!I38 -> 3649.4582
A41: ROIC % | B41: N/A | C41: N/A | D41: =Returns!B16 -> -0.001784079 | E41: =Returns!C16 -> 0.050108128 | F41: =Returns!D16 -> 0.079757916 | G41: =Returns!E16 -> 0.07764778 | H41: =Returns!F16 -> 0.079034471 | I41: =Returns!G16 -> 0.078441054
A42: ROE % | B42: N/A | C42: N/A | D42: =Returns!B21 -> -0.50269222 | E42: =Returns!C21 -> -0.049886444 | F42: =Returns!D21 -> 0.20390877 | G42: =Returns!E21 -> 0.18942133 | H42: =Returns!F21 -> 0.17563612 | I42: =Returns!G21 -> 0.14823844
A43: ROA % | B43: N/A | C43: N/A | D43: =Returns!B26 -> -0.03476577 | E43: =Returns!C26 -> -0.0042215108 | F43: =Returns!D26 -> 0.027272912 | G43: =Returns!E26 -> 0.036939136 | H43: =Returns!F26 -> 0.043946573 | I43: =Returns!G26 -> 0.045378559
A44: Net Debt / EBITDA | B44: N/A | C44: =IF(IS!C43=0,0,(BS!B23+BS!B29-BS!B5)/IS!C43) -> 5.3596059 | D44: =IF(IS!D43=0,0,(BS!C23+BS!C29-BS!C5)/IS!D43) -> 5.7251481 | E44: =IF(IS!E43=0,0,(BS!D23+BS!D29-BS!D5)/IS!E43) -> 3.6685579 | F44: =IF(IS!F43=0,0,(BS!E23+BS!E29-BS!E5)/IS!F43) -> 2.5720079 | G44: =IF(IS!G43=0,0,(BS!F23+BS!F29-BS!F5)/IS!G43) -> 2.1503177 | H44: =IF(IS!H43=0,0,(BS!G23+BS!G29-BS!G5)/IS!H43) -> 1.6345121 | I44: =IF(IS!I43=0,0,(BS!H23+BS!H29-BS!H5)/IS!I43) -> 1.2676004
A46: Revenue trajectory: $229M (FY23) → $5.1B (FY25) → $12.5B (FY26E) → $25B (FY30E). Near-term RPO-backed and near-certain; FY28+ dependent on $20-25B/yr new backlog (FY25's $50B net-new was a first-signing effect, not repeatable). 2030+ annualized RPO drops to ~$3.3B without new contracts — a revenue cliff risk.
A47: Margin outlook: Gross margin peaks ~72% (FY25) then normalizes to 66% by FY30E on GPU price pressure. EBITDA ~60% but excludes D&A — after $2.1B D&A, FY25 EBIT was -$0.24B. GAAP profitability requires $19-20B revenue (FY27E earliest, narrow window). Investment thesis must be EBITDA-based, not GAAP earnings.
A48: Capital allocation: Capex peaks $20B (FY26E cash basis) then decelerates to $10B by FY30E. FCF remains deeply negative through FY27 (-$7B to -$17B); earliest positive FY28-29. Until then, all equity returns are multiple-expansion dependent — no capital return capacity.
...

Sheet Assumptions
A1: CoreWeave (CRWV) — Model Assumptions
A2: Navy text = model inputs (editable). All forecast IS/BS/CF cells reference this tab.
A3: Assumption | B3: FY2026E | C3: FY2027E | D3: FY2028E | E3: FY2029E | F3: FY2030E | G3: Basis / Notes
A4: REVENUE
A5: Revenue ($M) | B5: 12500 | C5: 20000 | D5: 22000 | E5: 24000 | F5: 25000 | G5: FY26: mid guidance; FY27: base case memo; FY28-30: decel
A6: Revenue YoY % | B6: 1.436 | C6: 0.6 | D6: 0.1 | E6: 0.091 | F6: 0.042 | G6: FY26: 143.6%; deceleration path
A8: COST OF REVENUE & GROSS MARGIN
A9: Gross Margin % | B9: 0.7 | C9: 0.7 | D9: 0.68 | E9: 0.67 | F9: 0.66 | G9: FY25: 71.7%; pressure from GPU price decline 2028+
A10: COGS ($M) | B10: 3750 | C10: 6000 | D10: 7040 | E10: 7920 | F10: 8500
A12: OPERATING EXPENSES
A13: Tech & Infra % of Rev | B13: 0.45 | C13: 0.38 | D13: 0.34 | E13: 0.32 | F13: 0.31 | G13: FY25: 57.1%; declining with scale
A14: Sales & Marketing % of Rev | B14: 0.025 | C14: 0.025 | D14: 0.025 | E14: 0.025 | F14: 0.025 | G14: FY25: 2.8%; stable
A15: G&A % of Rev | B15: 0.055 | C15: 0.045 | D15: 0.04 | E15: 0.035 | F15: 0.035 | G15: FY25: 12.7% (incl SBC); normalize
A17: D&A / SBC / BELOW-LINE
A18: D&A ($M) | B18: 4500 | C18: 5800 | D18: 6500 | E18: 6800 | F18: 7000 | G18: PP&E growth driven; 6yr GPU life
A19: SBC ($M) | B19: 800 | C19: 900 | D19: 1000 | E19: 1050 | F19: 1100 | G19: FY25: $630M incl $177M one-time; normalize ~$800M+
A20: Interest Expense ($M) | B20: 2400 | C20: 2800 | D20: 2500 | E20: 2200 | F20: 2000 | G20: Memo mid $2.4B FY26; peaks FY27 then declines w/ deleverage
A21: Fair Value Adj ($M) | B21: 0 | C21: 0 | D21: 0 | E21: 0 | F21: 0 | G21: One-time items; assume nil forecast
A22: Other Income ($M) | B22: 30 | C22: 30 | D22: 30 | E22: 30 | F22: 30 | G22: Stable ~$30M
A23: Tax Rate % | B23: -0.04 | C23: 0.05 | D23: 0.1 | E23: 0.15 | F23: 0.18 | G23: FY25: benefit; normalize to 15-18% as profitable
A25: BALANCE SHEET — WORKING CAPITAL
A26: AR Days | B26: 85 | C26: 75 | D26: 70 | E26: 65 | F26: 65 | G26: FY25: 225d (extreme growth effect); normalize
A27: Prepaid & Other CA ($M) | B27: 500 | C27: 600 | D27: 650 | E27: 700 | F27: 700 | G27: Growth with revenue
A28: AP Days (of COGS) | B28: 120 | C28: 100 | D28: 90 | E28: 85 | F28: 80 | G28: FY25: 408d (GPU purchase lag); normalize
A29: Accrued Liabilities ($M) | B29: 6500 | C29: 7000 | D29: 7500 | E29: 7800 | F29: 8000 | G29: FY25: $5,773M; growth with ops scale
A30: Deferred Revenue Current ($M) | B30: 2500 | C30: 3000 | D30: 3200 | E30: 3400 | F30: 3500 | G30: RPO conversion; FY25: $1,709M
A31: Other Current Liab ($M) | B31: 800 | C31: 900 | D31: 950 | E31: 1000 | F31: 1000 | G31: Lease + other; FY25: $627M
A32: Deferred Revenue NC ($M) | B32: 8000 | C32: 10000 | D32: 11000 | E32: 11500 | F32: 10000 | G32: RPO backlog; FY25: $6,476M
A34: BALANCE SHEET — PP&E & INTANGIBLES
A35: Capex Cash ($M) | B35: 20000 | C35: 18000 | D35: 15000 | E35: 12000 | F35: 10000 | G35: Memo: $23-25B cash FY26; decel path
A36: PP&E Depreciation Rate % | B36: 0.12 | C36: 0.13 | D36: 0.14 | E36: 0.15 | F36: 0.15 | G36: ~6yr life = ~17%; ramp as fleet matures
A37: Intangibles Net ($M) | B37: 250 | C37: 230 | D37: 210 | E37: 190 | F37: 170 | G37: W&B amortization; FY25: $235M
A38: Goodwill ($M) | B38: 1101 | C38: 1101 | D38: 1101 | E38: 1101 | F38: 1101 | G38: No impairment assumed; FY25: $1,101M
A39: ROU Assets ($M) | B39: 10000 | C39: 12000 | D39: 13000 | E39: 13500 | F39: 13500 | G39: DC lease expansion; FY25: $8,231M
A40: Other Non-Current Assets ($M) | B40: 2000 | C40: 2200 | D40: 2400 | E40: 2500 | F40: 2500 | G40: Restricted cash + other; FY25: $1,690M
A42: BALANCE SHEET — LIABILITIES
A43: Debt Current ($M) | B43: 8000 | C43: 7000 | D43: 6500 | E43: 6000 | F43: 5500 | G43: Current portion; FY25: $6,708M
A44: Debt Non-Current ($M) | B44: 27000 | C44: 28000 | D44: 26000 | E44: 23000 | F44: 20000 | G44: Peak FY27-28 then deleverage; FY25: $14,665M
A45: Lease Liab NC ($M) | B45: 10000 | C45: 12000 | D45: 13000 | E45: 13500 | F45: 13500 | G45: ~= ROU assets; FY25: $7,984M
A46: Other NCL ($M) | B46: 500 | C46: 500 | D46: 500 | E46: 500 | F46: 500 | G46: Stable; FY25: $402M
...

Sheet IS
A1: CoreWeave, Inc. (CRWV) — Income Statement
A2: US GAAP | Units: $M | Annual
B3: FY2023 | C3: FY2024 | D3: FY2025 | E3: FY2026E | F3: FY2027E | G3: FY2028E | H3: FY2029E | I3: FY2030E | J3: Notes
A4: REVENUE
A5: Total Revenue | B5: =Raw_Info!B5 -> 229 | C5: =Raw_Info!C5 -> 1915 | D5: =Raw_Info!D5 -> 5131 | E5: =Assumptions!B5 -> 12500 | F5: =Assumptions!C5 -> 20000 | G5: =Assumptions!D5 -> 22000 | H5: =Assumptions!E5 -> 24000 | I5: =Assumptions!F5 -> 25000 | J5: FY26: mid guidance $12.5B; FY27: base case $20B
A6: ↳ Revenue YoY % | B6: ="" | C6: =IF(C4=0,0,(C5/B5-1)) -> 0 | D6: =IF(D4=0,0,(D5/C5-1)) -> 0 | E6: =E5/D5-1 -> 1.4361723 | F6: =F5/E5-1 -> 0.6 | G6: =G5/F5-1 -> 0.1 | H6: =H5/G5-1 -> 0.090909091 | I6: =I5/H5-1 -> 0.041666667 | J6: FY25: +168%; decelerating
A7: REV CHECK (Model - Source) | B7: =B5-Raw_Info!B5 -> 0 | C7: =C5-Raw_Info!C5 -> 0 | D7: =D5-Raw_Info!D5 -> 0 | E7: =E5-Assumptions!B5 -> 0 | F7: =F5-Assumptions!C5 -> 0 | G7: =G5-Assumptions!D5 -> 0 | H7: =H5-Assumptions!E5 -> 0 | I7: =I5-Assumptions!F5 -> 0 | J7: Must = 0 for all historical periods
A9: COST OF REVENUE & GROSS PROFIT
A10: Cost of Revenue | B10: =Raw_Info!B6 -> 69 | C10: =Raw_Info!C6 -> 493 | D10: =Raw_Info!D6 -> 1453 | E10: =E5*(1-Assumptions!B9) -> 3750 | F10: =F5*(1-Assumptions!C9) -> 6000 | G10: =G5*(1-Assumptions!D9) -> 7040 | H10: =H5*(1-Assumptions!E9) -> 7920 | I10: =I5*(1-Assumptions!F9) -> 8500 | J10: Forecast: Rev × (1 - GM%)
A11: Gross Profit | B11: =B5-B10 -> 160 | C11: =C5-C10 -> 1422 | D11: =D5-D10 -> 3678 | E11: =E5-E10 -> 8750 | F11: =F5-F10 -> 14000 | G11: =G5-G10 -> 14960 | H11: =H5-H10 -> 16080 | I11: =I5-I10 -> 16500 | J11: =Revenue - COGS -> #NAME?
A12: ↳ Gross Margin % | B12: =IF(B5=0,0,B11/B5) -> 0.69868996 | C12: =IF(C5=0,0,C11/C5) -> 0.74255875 | D12: =IF(D5=0,0,D11/D5) -> 0.71681933 | E12: =E11/E5 -> 0.7 | F12: =F11/F5 -> 0.7 | G12: =G11/G5 -> 0.68 | H12: =H11/H5 -> 0.67 | I12: =I11/I5 -> 0.66 | J12: FY25: 71.7%; forecast: 70%→66% on GPU price pressure
A14: OPERATING EXPENSES
A15: Technology & Infrastructure | B15: =Raw_Info!B8 -> 132 | C15: =Raw_Info!C8 -> 961 | D15: =Raw_Info!D8 -> 2929 | E15: =E5*Assumptions!B13 -> 5625 | F15: =F5*Assumptions!C13 -> 7600 | G15: =G5*Assumptions!D13 -> 7480 | H15: =H5*Assumptions!E13 -> 7680 | I15: =I5*Assumptions!F13 -> 7750 | J15: Incl R&D; FY25: 57.1% of rev → declining with scale
A16: Sales & Marketing | B16: =Raw_Info!B9 -> 13 | C16: =Raw_Info!C9 -> 18 | D16: =Raw_Info!D9 -> 144 | E16: =E5*Assumptions!B14 -> 312.5 | F16: =F5*Assumptions!C14 -> 500 | G16: =G5*Assumptions!D14 -> 550 | H16: =H5*Assumptions!E14 -> 600 | I16: =I5*Assumptions!F14 -> 625 | J16: FY25: 2.8% of rev; stable
A17: General & Administrative | B17: =Raw_Info!B10 -> 30 | C17: =Raw_Info!C10 -> 119 | D17: =Raw_Info!D10 -> 651 | E17: =E5*Assumptions!B15 -> 687.5 | F17: =F5*Assumptions!C15 -> 900 | G17: =G5*Assumptions!D15 -> 880 | H17: =H5*Assumptions!E15 -> 840 | I17: =I5*Assumptions!F15 -> 875 | J17: FY25: 12.7% (incl SBC); normalizing
A18: Total Operating Expenses (excl COGS) | B18: =B15+B16+B17 -> 175 | C18: =C15+C16+C17 -> 1098 | D18: =D15+D16+D17 -> 3724 | E18: =E15+E16+E17 -> 6625 | F18: =F15+F16+F17 -> 9000 | G18: =G15+G16+G17 -> 8910 | H18: =H15+H16+H17 -> 9120 | I18: =I15+I16+I17 -> 9250 | J18: =Tech&Infra + S&M + G&A -> #NAME?
A19: ↳ OpEx % of Revenue | B19: =IF(B5=0,0,B18/B5) -> 0.76419214 | C19: =IF(C5=0,0,C18/C5) -> 0.57336815 | D19: =IF(D5=0,0,D18/D5) -> 0.72578445 | E19: =E18/E5 -> 0.53 | F19: =F18/F5 -> 0.45 | G19: =G18/G5 -> 0.405 | H19: =H18/H5 -> 0.38 | I19: =I18/I5 -> 0.37 | J19: Target: declining with scale
A21: OPERATING INCOME
A22: Operating Income (Loss) | B22: =B11-B18 -> -15 | C22: =C11-C18 -> 324 | D22: =D11-D18 -> -46 | E22: =E11-E18 -> 2125 | F22: =F11-F18 -> 5000 | G22: =G11-G18 -> 6050 | H22: =H11-H18 -> 6960 | I22: =I11-I18 -> 7250 | J22: =GP - Total OpEx -> #NAME?
A23: ↳ Operating Margin % | B23: =IF(B5=0,0,B22/B5) -> -0.065502183 | C23: =IF(C5=0,0,C22/C5) -> 0.1691906 | D23: =IF(D5=0,0,D22/D5) -> -0.008965114 | E23: =E22/E5 -> 0.17 | F23: =F22/F5 -> 0.25 | G23: =G22/G5 -> 0.275 | H23: =H22/H5 -> 0.29 | I23: =I22/I5 -> 0.29 | J23: FY25: -0.9%; improving with scale
A25: BELOW THE LINE
A26: Fair Value Adj Gain/(Loss) | B26: =Raw_Info!B13 -> -534 | C26: =Raw_Info!C13 -> -756 | D26: =Raw_Info!D13 -> 27 | E26: =Assumptions!B21 -> 0 | F26: =Assumptions!C21 -> 0 | G26: =Assumptions!D21 -> 0 | H26: =Assumptions!E21 -> 0 | I26: =Assumptions!F21 -> 0 | J26: Warrant/derivative; assume nil forecast
A27: Interest Expense, net | B27: =Raw_Info!B14 -> -28 | C27: =Raw_Info!C14 -> -361 | D27: =Raw_Info!D14 -> -1229 | E27: =-Assumptions!B20 -> -2400 | F27: =-Assumptions!C20 -> -2800 | G27: =-Assumptions!D20 -> -2500 | H27: =-Assumptions!E20 -> -2200 | I27: =-Assumptions!F20 -> -2000 | J27: Memo: peaks FY27 $2.8B then declines; shown as negative
A28: Other Income, net | B28: =Raw_Info!B15 -> 19 | C28: =Raw_Info!C15 -> 49 | D28: =Raw_Info!D15 -> 33 | E28: =Assumptions!B22 -> 30 | F28: =Assumptions!C22 -> 30 | G28: =Assumptions!D22 -> 30 | H28: =Assumptions!E22 -> 30 | I28: =Assumptions!F22 -> 30 | J28: Stable ~$30M
A29: Income (Loss) Before Tax | B29: =B22+B26+B27+B28 -> -558 | C29: =C22+C26+C27+C28 -> -744 | D29: =D22+D26+D27+D28 -> -1215 | E29: =E22+E26+E27+E28 -> -245 | F29: =F22+F26+F27+F28 -> 2230 | G29: =G22+G26+G27+G28 -> 3580 | H29: =H22+H26+H27+H28 -> 4790 | I29: =I22+I26+I27+I28 -> 5280 | J29: =EBIT + FV Adj + Interest + Other -> #NAME?
A30: Income Tax Provision/(Benefit) | B30: =Raw_Info!B17 -> 36 | C30: =Raw_Info!C17 -> 119 | D30: =Raw_Info!D17 -> -48 | E30: =E29*Assumptions!B23 -> 9.8 | F30: =F29*Assumptions!C23 -> 111.5 | G30: =G29*Assumptions!D23 -> 358 | H30: =H29*Assumptions!E23 -> 718.5 | I30: =I29*Assumptions!F23 -> 950.4 | J30: FY25: benefit; normalizing to 15-18%
A31: ↳ Effective Tax Rate % | B31: =IF(B29=0,0,B30/B29) -> -0.064516129 | C31: =IF(C29=0,0,C30/C29) -> -0.15994624 | D31: =IF(D29=0,0,D30/D29) -> 0.039506173 | E31: =Assumptions!B23 -> -0.04 | F31: =Assumptions!C23 -> 0.05 | G31: =Assumptions!D23 -> 0.1 | H31: =Assumptions!E23 -> 0.15 | I31: =Assumptions!F23 -> 0.18 | J31: Normalizing from benefit to ~18%
A33: NET INCOME
A34: Net Income (Loss) | B34: =B29-B30 -> -594 | C34: =C29-C30 -> -863 | D34: =D29-D30 -> -1167 | E34: =E29-E30 -> -254.8 | F34: =F29-F30 -> 2118.5 | G34: =G29-G30 -> 3222 | H34: =H29-H30 -> 4071.5 | I34: =I29-I30 -> 4329.6 | J34: =PBT - Tax -> #NAME?
A35: ↳ Net Income Margin % | B35: =IF(B5=0,0,B34/B5) -> -2.5938865 | C35: =IF(C5=0,0,C34/C5) -> -0.45065274 | D35: =IF(D5=0,0,D34/D5) -> -0.22744104 | E35: =E34/E5 -> -0.020384 | F35: =F34/F5 -> 0.105925 | G35: =G34/G5 -> 0.14645455 | H35: =H34/H5 -> 0.16964583 | I35: =I34/I5 -> 0.173184 | J35: GAAP profitability expected FY2027+ bull case
A36: NI CHECK (Model - Source) | B36: =B34-Raw_Info!B18 -> 0 | C36: =C34-Raw_Info!C18 -> 0 | D36: =D34-Raw_Info!D18 -> 0 | E36: =E34-(E29-E30) -> 0 | F36: =F34-(F29-F30) -> 0 | G36: =G34-(G29-G30) -> 0 | H36: =H34-(H29-H30) -> 0 | I36: =I34-(I29-I30) -> 0 | J36: Must = 0 for all historical periods
A37: Attr. to Common Stockholders | B37: =B34 -> -594 | C37: =C34 -> -863 | D37: =D34 -> -1167 | E37: =E34 -> -254.8 | F37: =F34 -> 2118.5 | G37: =G34 -> 3222 | H37: =H34 -> 4071.5 | I37: =I34 -> 4329.6
A38: Attr. to NCI | B38: =0 -> 0 | C38: =0 -> 0 | D38: =0 -> 0 | E38: =0 -> 0 | F38: =0 -> 0 | G38: =0 -> 0 | H38: =0 -> 0 | I38: =0 -> 0 | J38: No NCI reported in CoreWeave 10-K
A40: MEMO ITEMS
A41: D&A (Depreciation & Amortization) | B41: =Raw_Info!B19 -> 103 | C41: =Raw_Info!C19 -> 863 | D41: =Raw_Info!D19 -> 2454 | E41: =Assumptions!B18 -> 4500 | F41: =Assumptions!C18 -> 5800 | G41: =Assumptions!D18 -> 6500 | H41: =Assumptions!E18 -> 6800 | I41: =Assumptions!F18 -> 7000 | J41: PP&E + intangible; 6yr GPU life; from CF supplement
A42: Stock-Based Compensation | B42: =Raw_Info!B20 -> 15 | C42: =Raw_Info!C20 -> 31 | D42: =Raw_Info!D20 -> 630 | E42: =Assumptions!B19 -> 800 | F42: =Assumptions!C19 -> 900 | G42: =Assumptions!D19 -> 1000 | H42: =Assumptions!E19 -> 1050 | I42: =Assumptions!F19 -> 1100 | J42: FY25: $630M incl $177M IPO one-time
A43: Adj. EBITDA | B43: =B22+B41+B42 -> 103 | C43: =C22+C41+C42 -> 1218 | D43: =D22+D41+D42 -> 3038 | E43: =E22+E41+E42 -> 7425 | F43: =F22+F41+F42 -> 11700 | G43: =G22+G41+G42 -> 13550 | H43: =H22+H41+H42 -> 14810 | I43: =I22+I41+I42 -> 15350 | J43: =EBIT + D&A + SBC -> #NAME?
A44: ↳ EBITDA Margin % | B44: =IF(B5=0,0,B43/B5) -> 0.44978166 | C44: =IF(C5=0,0,C43/C5) -> 0.63603133 | D44: =IF(D5=0,0,D43/D5) -> 0.59208731 | E44: =E43/E5 -> 0.594 | F44: =F43/F5 -> 0.585 | G44: =G43/G5 -> 0.61590909 | H44: =H43/H5 -> 0.61708333 | I44: =I43/I5 -> 0.614 | J44: FY25: 60.2%; Memo: target 55-60%
A45: EPS (Basic) | B45: =IF(Raw_Info!D110=0,0,B34/Raw_Info!D110) -> -1.129922 | C45: =IF(Raw_Info!D110=0,0,C34/Raw_Info!D110) -> -1.6416207 | D45: =IF(Raw_Info!D110=0,0,D34/Raw_Info!D110) -> -2.2198973 | E45: =E34/Assumptions!B50 -> -0.46752294 | F45: =F34/Assumptions!C50 -> 3.7166667 | G45: =G34/Assumptions!D50 -> 5.37 | H45: =H34/Assumptions!E50 -> 6.5669355 | I45: =I34/Assumptions!F50 -> 6.8182677 | J45: Basic EPS; diluted would be lower

Sheet BS
A1: CoreWeave, Inc. (CRWV) — Balance Sheet
A2: US GAAP | Units: $M | Annual
B3: FY2024 | C3: FY2025 | D3: FY2026E | E3: FY2027E | F3: FY2028E | G3: FY2029E | H3: FY2030E | I3: Notes
A4: CURRENT ASSETS
A5: Cash & Equivalents | B5: =Raw_Info!C31 -> 1398 | C5: =Raw_Info!D31 -> 3980 | D5: =CF!E33 -> 7760.9578 | E5: =CF!F33 -> 4907.5074 | F5: =CF!G33 -> 3363.1946 | G5: =CF!H33 -> 4792.8759 | H5: =CF!I33 -> 6042.3341
A6: Accounts Receivable, net | B6: =Raw_Info!C32 -> 417 | C6: =Raw_Info!D32 -> 3169 | D6: =IS!E5*Assumptions!B26/365 -> 2910.9589 | E6: =IS!F5*Assumptions!C26/365 -> 4109.589 | F6: =IS!G5*Assumptions!D26/365 -> 4219.1781 | G6: =IS!H5*Assumptions!E26/365 -> 4273.9726 | H6: =IS!I5*Assumptions!F26/365 -> 4452.0548 | I6: =Revenue * AR Days / 365 -> #NAME?
A7: Prepaid & Other Current | B7: =Raw_Info!C33 -> 101 | C7: =Raw_Info!D33 -> 339 | D7: =Assumptions!B27 -> 500 | E7: =Assumptions!C27 -> 600 | F7: =Assumptions!D27 -> 650 | G7: =Assumptions!E27 -> 700 | H7: =Assumptions!F27 -> 700 | I7: Growth with revenue scale
A8: Total Current Assets | B8: =B5+B6+B7 -> 1916 | C8: =C5+C6+C7 -> 7488 | D8: =D5+D6+D7 -> 11171.917 | E8: =E5+E6+E7 -> 9617.0964 | F8: =F5+F6+F7 -> 8232.3727 | G8: =G5+G6+G7 -> 9766.8485 | H8: =H5+H6+H7 -> 11194.389 | I8: =Cash + AR + Prepaid -> #NAME?
A10: NON-CURRENT ASSETS
A11: PP&E, net | B11: =Raw_Info!C35 -> 11915 | C11: =Raw_Info!D35 -> 30557 | D11: =C11*(1-Assumptions!B36)+Assumptions!B35 -> 46890.16 | E11: =D11*(1-Assumptions!C36)+Assumptions!C35 -> 58794.439 | F11: =E11*(1-Assumptions!D36)+Assumptions!D35 -> 65563.218 | G11: =F11*(1-Assumptions!E36)+Assumptions!E35 -> 67728.735 | H11: =G11*(1-Assumptions!F36)+Assumptions!F35 -> 67569.425
A12: Intangible Assets, net | B12: =Raw_Info!C36 -> 5 | C12: =Raw_Info!D36 -> 235 | D12: =Assumptions!B37 -> 250 | E12: =Assumptions!C37 -> 230 | F12: =Assumptions!D37 -> 210 | G12: =Assumptions!E37 -> 190 | H12: =Assumptions!F37 -> 170 | I12: W&B amortization; declining
A13: Goodwill | B13: =Raw_Info!C37 -> 20 | C13: =Raw_Info!D37 -> 1101 | D13: =Assumptions!B38 -> 1101 | E13: =Assumptions!C38 -> 1101 | F13: =Assumptions!D38 -> 1101 | G13: =Assumptions!E38 -> 1101 | H13: =Assumptions!F38 -> 1101 | I13: Flat unless impairment; W&B $1.1B
A14: ROU Assets (Operating Lease) | B14: =Raw_Info!C38 -> 2590 | C14: =Raw_Info!D38 -> 8231 | D14: =Assumptions!B39 -> 10000 | E14: =Assumptions!C39 -> 12000 | F14: =Assumptions!D39 -> 13000 | G14: =Assumptions!E39 -> 13500 | H14: =Assumptions!F39 -> 13500 | I14: DC lease expansion; FY25: $8.2B
A15: Other Non-Current Assets | B15: =Raw_Info!C39 -> 1387 | C15: =Raw_Info!D39 -> 1690 | D15: =Assumptions!B40 -> 2000 | E15: =Assumptions!C40 -> 2200 | F15: =Assumptions!D40 -> 2400 | G15: =Assumptions!E40 -> 2500 | H15: =Assumptions!F40 -> 2500 | I15: Restricted cash + other
A16: Total Non-Current Assets | B16: =B11+B12+B13+B14+B15 -> 15917 | C16: =C11+C12+C13+C14+C15 -> 41814 | D16: =D11+D12+D13+D14+D15 -> 60241.16 | E16: =E11+E12+E13+E14+E15 -> 74325.439 | F16: =F11+F12+F13+F14+F15 -> 82274.218 | G16: =G11+G12+G13+G14+G15 -> 85019.735 | H16: =H11+H12+H13+H14+H15 -> 84840.425 | I16: =PP&E + Intang + GW + ROU + Other NCA -> #NAME?
A18: TOTAL ASSETS | B18: =B8+B16 -> 17833 | C18: =C8+C16 -> 49302 | D18: =D8+D16 -> 71413.077 | E18: =E8+E16 -> 83942.536 | F18: =F8+F16 -> 90506.59 | G18: =G8+G16 -> 94786.584 | H18: =H8+H16 -> 96034.814 | I18: =Total CA + Total NCA -> #NAME?
A20: CURRENT LIABILITIES
A21: Accounts Payable | B21: =Raw_Info!C42 -> 868 | C21: =Raw_Info!D42 -> 1623 | D21: =IS!E10*Assumptions!B28/365 -> 1232.8767 | E21: =IS!F10*Assumptions!C28/365 -> 1643.8356 | F21: =IS!G10*Assumptions!D28/365 -> 1735.8904 | G21: =IS!H10*Assumptions!E28/365 -> 1844.3836 | H21: =IS!I10*Assumptions!F28/365 -> 1863.0137 | I21: =COGS * AP Days / 365 -> #NAME?
A22: Accrued Liabilities | B22: =Raw_Info!C43 -> 356 | C22: =Raw_Info!D43 -> 5773 | D22: =Assumptions!B29 -> 6500 | E22: =Assumptions!C29 -> 7000 | F22: =Assumptions!D29 -> 7500 | G22: =Assumptions!E29 -> 7800 | H22: =Assumptions!F29 -> 8000 | I22: Growth with operations scale
A23: Debt, current | B23: =Raw_Info!C44 -> 2468 | C23: =Raw_Info!D44 -> 6708 | D23: =Assumptions!B43 -> 8000 | E23: =Assumptions!C43 -> 7000 | F23: =Assumptions!D43 -> 6500 | G23: =Assumptions!E43 -> 6000 | H23: =Assumptions!F43 -> 5500 | I23: Current portion of LT debt
A24: Deferred Revenue, current | B24: =Raw_Info!C45 -> 769 | C24: =Raw_Info!D45 -> 1709 | D24: =Assumptions!B30 -> 2500 | E24: =Assumptions!C30 -> 3000 | F24: =Assumptions!D30 -> 3200 | G24: =Assumptions!E30 -> 3400 | H24: =Assumptions!F30 -> 3500 | I24: RPO conversion; take-or-pay
A25: Other Current Liabilities | B25: =Raw_Info!C46 -> 502 | C25: =Raw_Info!D46 -> 627 | D25: =Assumptions!B31 -> 800 | E25: =Assumptions!C31 -> 900 | F25: =Assumptions!D31 -> 950 | G25: =Assumptions!E31 -> 1000 | H25: =Assumptions!F31 -> 1000 | I25: Lease + other
A26: Total Current Liabilities | B26: =B21+B22+B23+B24+B25 -> 4963 | C26: =C21+C22+C23+C24+C25 -> 16440 | D26: =D21+D22+D23+D24+D25 -> 19032.877 | E26: =E21+E22+E23+E24+E25 -> 19543.836 | F26: =F21+F22+F23+F24+F25 -> 19885.89 | G26: =G21+G22+G23+G24+G25 -> 20044.384 | H26: =H21+H22+H23+H24+H25 -> 19863.014 | I26: =AP + Accrued + Debt_curr + DefRev + Other CL -> #NAME?
A28: NON-CURRENT LIABILITIES
A29: Debt, non-current | B29: =Raw_Info!C48 -> 5458 | C29: =Raw_Info!D48 -> 14665 | D29: =Assumptions!B44 -> 27000 | E29: =Assumptions!C44 -> 28000 | F29: =Assumptions!D44 -> 26000 | G29: =Assumptions!E44 -> 23000 | H29: =Assumptions!F44 -> 20000 | I29: Peak FY27-28 then deleverage
A30: Deferred Revenue, non-current | B30: =Raw_Info!C49 -> 3295 | C30: =Raw_Info!D49 -> 6476 | D30: =Assumptions!B32 -> 8000 | E30: =Assumptions!C32 -> 10000 | F30: =Assumptions!D32 -> 11000 | G30: =Assumptions!E32 -> 11500 | H30: =Assumptions!F32 -> 10000 | I30: Long-term RPO backlog
A31: Lease Liabilities, non-current | B31: =Raw_Info!C50 -> 2423 | C31: =Raw_Info!D50 -> 7984 | D31: =Assumptions!B45 -> 10000 | E31: =Assumptions!C45 -> 12000 | F31: =Assumptions!D45 -> 13000 | G31: =Assumptions!E45 -> 13500 | H31: =Assumptions!F45 -> 13500 | I31: ~= ROU assets
A32: Other Non-Current Liabilities | B32: =Raw_Info!C51 -> 386 | C32: =Raw_Info!D51 -> 402 | D32: =Assumptions!B46 -> 500 | E32: =Assumptions!C46 -> 500 | F32: =Assumptions!D46 -> 500 | G32: =Assumptions!E46 -> 500 | H32: =Assumptions!F46 -> 500 | I32: Stable ~$500M
A33: Total Non-Current Liabilities | B33: =B29+B30+B31+B32 -> 11562 | C33: =C29+C30+C31+C32 -> 29527 | D33: =D29+D30+D31+D32 -> 45500 | E33: =E29+E30+E31+E32 -> 50500 | F33: =F29+F30+F31+F32 -> 50500 | G33: =G29+G30+G31+G32 -> 48500 | H33: =H29+H30+H31+H32 -> 44000 | I33: =Debt_NC + DefRev_NC + Lease_NC + Other NCL -> #NAME?
A35: TOTAL LIABILITIES | B35: =B26+B33 -> 16525 | C35: =C26+C33 -> 45967 | D35: =D26+D33 -> 64532.877 | E35: =E26+E33 -> 70043.836 | F35: =F26+F33 -> 70385.89 | G35: =G26+G33 -> 68544.384 | H35: =H26+H33 -> 63863.014 | I35: =Total CL + Total NCL -> #NAME?
A37: STOCKHOLDERS' EQUITY
A38: Mezzanine Equity (Redeemable Pref) | B38: =Raw_Info!C54 -> 1722 | C38: =Raw_Info!D54 -> 0 | D38: =0 -> 0 | E38: =0 -> 0 | F38: =0 -> 0 | G38: =0 -> 0 | H38: =0 -> 0 | I38: Converted at IPO March 2025; 0 thereafter
A39: Treasury Stock | B39: =Raw_Info!C55 -> -34 | C39: =Raw_Info!D55 -> -34 | D39: =-34 -> -34 | E39: =-34 -> -34 | F39: =-34 -> -34 | G39: =-34 -> -34 | H39: =-34 -> -34 | I39: Flat at -$34M
A40: Additional Paid-In Capital (APIC) | B40: =Raw_Info!C56 -> 1096 | C40: =Raw_Info!D56 -> 6012 | D40: =C40+IS!E42+Assumptions!B49 -> 9812 | E40: =D40+IS!F42+Assumptions!C49 -> 14712 | F40: =E40+IS!G42+Assumptions!D49 -> 17712 | G40: =F40+IS!H42+Assumptions!E49 -> 19762 | H40: =G40+IS!I42+Assumptions!F49 -> 21362 | I40: =Prior + SBC + Equity Issuance -> #NAME?
A41: Accumulated Deficit | B41: =Raw_Info!C57 -> -1476 | C41: =Raw_Info!D57 -> -2643 | D41: =C41+IS!E34 -> -2897.8 | E41: =D41+IS!F34 -> -779.3 | F41: =E41+IS!G34 -> 2442.7 | G41: =F41+IS!H34 -> 6514.2 | H41: =G41+IS!I34 -> 10843.8
A42: Total Stockholders' Equity | B42: =B38+B39+B40+B41 -> 1308 | C42: =C38+C39+C40+C41 -> 3335 | D42: =D38+D39+D40+D41 -> 6880.2 | E42: =E38+E39+E40+E41 -> 13898.7 | F42: =F38+F39+F40+F41 -> 20120.7 | G42: =G38+G39+G40+G41 -> 26242.2 | H42: =H38+H39+H40+H41 -> 32171.8 | I42: =Mezz + Treasury + APIC + Accum Deficit -> #NAME?
A43: Non-Controlling Interest | B43: =0 -> 0 | C43: =0 -> 0 | D43: =0 -> 0 | E43: =0 -> 0 | F43: =0 -> 0 | G43: =0 -> 0 | H43: =0 -> 0 | I43: No NCI reported per 10-K
A45: TOTAL LIABILITIES + EQUITY | B45: =B35+B42+B43 -> 17833 | C45: =C35+C42+C43 -> 49302 | D45: =D35+D42+D43 -> 71413.077 | E45: =E35+E42+E43 -> 83942.536 | F45: =F35+F42+F43 -> 90506.59 | G45: =G35+G42+G43 -> 94786.584 | H45: =H35+H42+H43 -> 96034.814 | I45: =Total Liab + Total Equity + NCI -> #NAME?
A47: BS CHECK (TA - TLE) | B47: =B18-B45 -> 0 | C47: =C18-C45 -> 0 | D47: =D18-D45 -> 0 | E47: =E18-E45 -> 0 | F47: =F18-F45 -> 0 | G47: =G18-G45 -> 0 | H47: =H18-H45 -> 0

Sheet CF
A1: CoreWeave, Inc. (CRWV) — Cash Flow Statement
A2: US GAAP | Units: $M | Annual | Indirect Method
B3: FY2023 | C3: FY2024 | D3: FY2025 | E3: FY2026E | F3: FY2027E | G3: FY2028E | H3: FY2029E | I3: FY2030E | J3: Notes
A4: OPERATING ACTIVITIES
A5: Net Income (Loss) | B5: =Raw_Info!B62 -> -594 | C5: =Raw_Info!C62 -> -863 | D5: =Raw_Info!D62 -> -1167 | E5: =IS!E34 -> -254.8 | F5: =IS!F34 -> 2118.5 | G5: =IS!G34 -> 3222 | H5: =IS!H34 -> 4071.5 | I5: =IS!I34 -> 4329.6 | J5: =IS Net Income -> #NAME?
A6: Depreciation & Amortization | B6: =Raw_Info!B63 -> 103 | C6: =Raw_Info!C63 -> 863 | D6: =Raw_Info!D63 -> 2454 | E6: =IS!E41 -> 4500 | F6: =IS!F41 -> 5800 | G6: =IS!G41 -> 6500 | H6: =IS!H41 -> 6800 | I6: =IS!I41 -> 7000 | J6: =IS D&A memo item -> #NAME?
A7: Stock-Based Compensation | B7: =Raw_Info!B64 -> 15 | C7: =Raw_Info!C64 -> 31 | D7: =Raw_Info!D64 -> 630 | E7: =IS!E42 -> 800 | F7: =IS!F42 -> 900 | G7: =IS!G42 -> 1000 | H7: =IS!H42 -> 1050 | I7: =IS!I42 -> 1100 | J7: =IS SBC memo item -> #NAME?
A8: Δ AR (asset ↑ = cash out) | B8: =0 -> 0 | C8: =0 -> 0 | D8: =0 -> 0 | E8: =-(BS!D6-BS!C6) -> 258.0411 | F8: =-(BS!E6-BS!D6) -> -1198.6301 | G8: =-(BS!F6-BS!E6) -> -109.58904 | H8: =-(BS!G6-BS!F6) -> -54.794521 | I8: =-(BS!H6-BS!G6) -> -178.08219 | J8: =-(Current AR - Prior AR) -> #NAME?
A9: Δ Prepaid & Other (asset ↑ = cash out) | B9: =0 -> 0 | C9: =0 -> 0 | D9: =0 -> 0 | E9: =-(BS!D7-BS!C7) -> -161 | F9: =-(BS!E7-BS!D7) -> -100 | G9: =-(BS!F7-BS!E7) -> -50 | H9: =-(BS!G7-BS!F7) -> -50 | I9: =-(BS!H7-BS!G7) -> 0 | J9: =-(Current - Prior) -> #NAME?
A10: Δ AP (liab ↑ = cash in) | B10: =0 -> 0 | C10: =0 -> 0 | D10: =0 -> 0 | E10: =BS!D21-BS!C21 -> -390.12329 | F10: =BS!E21-BS!D21 -> 410.9589 | G10: =BS!F21-BS!E21 -> 92.054795 | H10: =BS!G21-BS!F21 -> 108.49315 | I10: =BS!H21-BS!G21 -> 18.630137 | J10: =Current AP - Prior AP -> #NAME?
A11: Δ Accrued Liabilities (liab ↑ = cash in) | B11: =0 -> 0 | C11: =0 -> 0 | D11: =0 -> 0 | E11: =BS!D22-BS!C22 -> 727 | F11: =BS!E22-BS!D22 -> 500 | G11: =BS!F22-BS!E22 -> 500 | H11: =BS!G22-BS!F22 -> 300 | I11: =BS!H22-BS!G22 -> 200 | J11: =Current - Prior -> #NAME?
A12: Δ Deferred Revenue (liab ↑ = cash in) | B12: =0 -> 0 | C12: =0 -> 0 | D12: =0 -> 0 | E12: =(BS!D24+BS!D30)-(BS!C24+BS!C30) -> 2315 | F12: =(BS!E24+BS!E30)-(BS!D24+BS!D30) -> 2500 | G12: =(BS!F24+BS!F30)-(BS!E24+BS!E30) -> 1200 | H12: =(BS!G24+BS!G30)-(BS!F24+BS!F30) -> 700 | I12: =(BS!H24+BS!H30)-(BS!G24+BS!G30) -> -1400 | J12: =Current+NC DefRev change -> #NAME?
A13: Working Capital Changes (Total) | B13: =Raw_Info!B65 -> 1702 | C13: =Raw_Info!C65 -> 1678 | D13: =Raw_Info!D65 -> 632 | E13: =SUM(E8:E12) -> 2748.9178 | F13: =SUM(F8:F12) -> 2112.3288 | G13: =SUM(G8:G12) -> 1632.4658 | H13: =SUM(H8:H12) -> 1003.6986 | I13: =SUM(I8:I12) -> -1359.4521 | J13: Hist: Raw_Info aggregate; Fcst: sum of Δ rows
A14: Other Non-Cash Items | B14: =Raw_Info!B66 -> 607 | C14: =Raw_Info!C66 -> 1040 | D14: =Raw_Info!D66 -> 509 | E14: =Assumptions!B58 -> 300 | F14: =Assumptions!C58 -> 200 | G14: =Assumptions!D58 -> 150 | H14: =Assumptions!E58 -> 100 | I14: =Assumptions!F58 -> 100 | J14: FV adj, other; declining as ops stabilize
A15: Non-Cash Adj — Others (R3 Plug) | B15: =0 -> 0 | C15: =0 -> 0 | D15: =0 -> 0 | E15: =BS!D45-BS!D16-SUM(BS!D6:'BS'!D7)-BS!C5-E5-E6-E7-E13-E14-E22-E28 -> 1386.84 | F15: =BS!E45-BS!E16-SUM(BS!E6:'BS'!E7)-BS!D5-F5-F6-F7-F13-F14-F22-F28 -> -7184.2792 | G15: =BS!F45-BS!F16-SUM(BS!F6:'BS'!F7)-BS!E5-G5-G6-G7-G13-G14-G22-G28 -> -3148.7785 | H15: =BS!G45-BS!G16-SUM(BS!G6:'BS'!G7)-BS!F5-H5-H6-H7-H13-H14-H22-H28 -> 304.48266 | I15: =BS!H45-BS!H16-SUM(BS!H6:'BS'!H7)-BS!G5-I5-I6-I7-I13-I14-I22-I28 -> 2479.3103 | J15: R3 plug; forecast formula written after CFI/CFF
A16: CFO Total | B16: =Raw_Info!B67 -> 1833 | C16: =Raw_Info!C67 -> 2749 | D16: =Raw_Info!D67 -> 3058 | E16: =E5+E6+E7+E13+E14+E15 -> 9480.9578 | F16: =F5+F6+F7+F13+F14+F15 -> 3946.5496 | G16: =G5+G6+G7+G13+G14+G15 -> 9355.6872 | H16: =H5+H6+H7+H13+H14+H15 -> 13329.681 | I16: =I5+I6+I7+I13+I14+I15 -> 13649.458 | J16: =NI + D&A + SBC + WC + Other + Others plug -> #NAME?
A18: INVESTING ACTIVITIES
A19: Capex (PP&E purchases) | B19: =Raw_Info!B68 -> -2943 | C19: =Raw_Info!C68 -> -8702 | D19: =Raw_Info!D68 -> -10309 | E19: =-Assumptions!B35 -> -20000 | F19: =-Assumptions!C35 -> -18000 | G19: =-Assumptions!D35 -> -15000 | H19: =-Assumptions!E35 -> -12000 | I19: =-Assumptions!F35 -> -10000 | J19: Cash capex; shown as negative
A20: Acquisitions | B20: =Raw_Info!B69 -> 0 | C20: =Raw_Info!C69 -> 0 | D20: =Raw_Info!D69 -> -108 | E20: =Assumptions!B56 -> 0 | F20: =Assumptions!C56 -> 0 | G20: =Assumptions!D56 -> 0 | H20: =Assumptions!E56 -> 0 | I20: =Assumptions!F56 -> 0 | J20: No major M&A assumed forecast
A21: Other Investing | B21: =Raw_Info!B70 -> -205 | C21: =Raw_Info!C70 -> 44 | D21: =Raw_Info!D70 -> 146 | E21: =Assumptions!B57 -> 0 | F21: =Assumptions!C57 -> 0 | G21: =Assumptions!D57 -> 0 | H21: =Assumptions!E57 -> 0 | I21: =Assumptions!F57 -> 0 | J21: Net zero assumed forecast
A22: CFI Total | B22: =Raw_Info!B71 -> -3148 | C22: =Raw_Info!C71 -> -8658 | D22: =Raw_Info!D71 -> -10271 | E22: =E19+E20+E21 -> -20000 | F22: =F19+F20+F21 -> -18000 | G22: =G19+G20+G21 -> -15000 | H22: =H19+H20+H21 -> -12000 | I22: =I19+I20+I21 -> -10000 | J22: =Capex + Acquisitions + Other -> #NAME?
A24: FINANCING ACTIVITIES
A25: Net Debt Proceeds/(Repayments) | B25: =Raw_Info!B72+Raw_Info!B73 -> 1414 | C25: =Raw_Info!C72+Raw_Info!C73 -> 6429 | D25: =Raw_Info!D72+Raw_Info!D73 -> 8430 | E25: =Assumptions!B54 -> 12000 | F25: =Assumptions!C54 -> 8000 | G25: =Assumptions!D54 -> 3000 | H25: =Assumptions!E54 -> 0 | I25: =Assumptions!F54 -> -2000 | J25: =Debt Proceeds - Repayments -> #NAME?
A26: Equity Issuance | B26: =Raw_Info!B74 -> 437 | C26: =Raw_Info!C74 -> 1175 | D26: =Raw_Info!D74 -> 1511 | E26: =Assumptions!B49 -> 3000 | F26: =Assumptions!C49 -> 4000 | G26: =Assumptions!D49 -> 2000 | H26: =Assumptions!E49 -> 1000 | I26: =Assumptions!F49 -> 500 | J26: IPO + strategic investments
A27: Other Financing | B27: =Raw_Info!B75 -> -63 | C27: =Raw_Info!C75 -> -140 | D27: =Raw_Info!D75 -> -633 | E27: =Assumptions!B55 -> -700 | F27: =Assumptions!C55 -> -800 | G27: =Assumptions!D55 -> -900 | H27: =Assumptions!E55 -> -900 | I27: =Assumptions!F55 -> -900 | J27: Lease payments + other
A28: CFF Total | B28: =Raw_Info!B76 -> 1788 | C28: =Raw_Info!C76 -> 7464 | D28: =Raw_Info!D76 -> 9308 | E28: =E25+E26+E27 -> 14300 | F28: =F25+F26+F27 -> 11200 | G28: =G25+G26+G27 -> 4100 | H28: =H25+H26+H27 -> 100 | I28: =I25+I26+I27 -> -2400 | J28: =Net Debt + Equity Issuance + Other -> #NAME?
A30: CASH RECONCILIATION
A31: Net Change in Cash | B31: =Raw_Info!B77 -> 473 | C31: =Raw_Info!C77 -> 1555 | D31: =Raw_Info!D77 -> 2095 | E31: =E16+E22+E28 -> 3780.9578 | F31: =F16+F22+F28 -> -2853.4504 | G31: =G16+G22+G28 -> -1544.3128 | H31: =H16+H22+H28 -> 1429.6813 | I31: =I16+I22+I28 -> 1249.4582 | J31: =CFO + CFI + CFF -> #NAME?
A32: Beginning Cash | B32: =Raw_Info!B78 -> 7 | C32: =Raw_Info!C78 -> 480 | D32: =Raw_Info!D78 -> 2035 | E32: =BS!C5 -> 3980 | F32: =BS!D5 -> 7760.9578 | G32: =BS!E5 -> 4907.5074 | H32: =BS!F5 -> 3363.1946 | I32: =BS!G5 -> 4792.8759 | J32: =Prior year BS Cash -> #NAME?
A33: Ending Cash | B33: =Raw_Info!B79 -> 480 | C33: =Raw_Info!C79 -> 2035 | D33: =Raw_Info!D79 -> 4130 | E33: =E32+E31 -> 7760.9578 | F33: =F32+F31 -> 4907.5074 | G33: =G32+G31 -> 3363.1946 | H33: =H32+H31 -> 4792.8759 | I33: =I32+I31 -> 6042.3341 | J33: Incl restricted cash per 10-K CF reconciliation
A35: CF CHECK (Ending Cash - BS Cash) | B35: =0 -> 0 | C35: =C33-BS!B5 -> 637 | D35: =D33-BS!C5 -> 150 | E35: =E33-BS!D5 -> 0 | F35: =F33-BS!E5 -> 0 | G35: =G33-BS!F5 -> 0 | H35: =H33-BS!G5 -> 0 | I35: =I33-BS!H5 -> 0 | J35: Hist gap ≡ restricted cash (CF incl, BS excl); Forecast ≡ 0 by construction
A37: FREE CASH FLOW (MEMO)
A38: Free Cash Flow (CFO + Capex) | B38: =B16+B19 -> -1110 | C38: =C16+C19 -> -5953 | D38: =D16+D19 -> -7251 | E38: =E16+E19 -> -10519.042 | F38: =F16+F19 -> -14053.45 | G38: =G16+G19 -> -5644.3128 | H38: =H16+H19 -> 1329.6813 | I38: =I16+I19 -> 3649.4582

Sheet Returns
A1: CoreWeave, Inc. (CRWV) — Returns Analysis
A2: US GAAP | Units: $M | Annual
B3: FY2025 | C3: FY2026E | D3: FY2027E | E3: FY2028E | F3: FY2029E | G3: FY2030E
A4: RETURN ON INVESTED CAPITAL (ROIC)
A5: EBIT | B5: =IS!D22 -> -46 | C5: =IS!E22 -> 2125 | D5: =IS!F22 -> 5000 | E5: =IS!G22 -> 6050 | F5: =IS!H22 -> 6960 | G5: =IS!I22 -> 7250
A6: Effective Tax Rate % | B6: =IS!D31 -> 0.039506173 | C6: =IS!E31 -> -0.04 | D6: =IS!F31 -> 0.05 | E6: =IS!G31 -> 0.1 | F6: =IS!H31 -> 0.15 | G6: =IS!I31 -> 0.18
A7: NOPAT | B7: =B5*(1-B6) -> -44.182716 | C7: =C5*(1-C6) -> 2210 | D7: =D5*(1-D6) -> 4750 | E7: =E5*(1-E6) -> 5445 | F7: =F5*(1-F6) -> 5916 | G7: =G5*(1-G6) -> 5945
A9: INVESTED CAPITAL
A10: Current Assets (excl Cash) | B10: =BS!C8-BS!C5 -> 3508 | C10: =BS!D8-BS!D5 -> 3410.9589 | D10: =BS!E8-BS!E5 -> 4709.589 | E10: =BS!F8-BS!F5 -> 4869.1781 | F10: =BS!G8-BS!G5 -> 4973.9726 | G10: =BS!H8-BS!H5 -> 5152.0548
A11: Current Liabilities (excl ST Debt) | B11: =BS!C26-BS!C23 -> 9732 | C11: =BS!D26-BS!D23 -> 11032.877 | D11: =BS!E26-BS!E23 -> 12543.836 | E11: =BS!F26-BS!F23 -> 13385.89 | F11: =BS!G26-BS!G23 -> 14044.384 | G11: =BS!H26-BS!H23 -> 14363.014
A12: Net Working Capital (NWC) | B12: =B10-B11 -> -6224 | C12: =C10-C11 -> -7621.9178 | D12: =D10-D11 -> -7834.2466 | E12: =E10-E11 -> -8516.7123 | F12: =F10-F11 -> -9070.411 | G12: =G10-G11 -> -9210.9589
A13: Net LT Operating Assets | B13: =BS!C16 -> 41814 | C13: =BS!D16 -> 60241.16 | D13: =BS!E16 -> 74325.439 | E13: =BS!F16 -> 82274.218 | F13: =BS!G16 -> 85019.735 | G13: =BS!H16 -> 84840.425
A14: Invested Capital (IC) | B14: =B12+B13 -> 35590 | C14: =C12+C13 -> 52619.242 | D14: =D12+D13 -> 66491.193 | E14: =E12+E13 -> 73757.505 | F14: =F12+F13 -> 75949.324 | G14: =G12+G13 -> 75629.466
A15: Average IC | B15: =(B14+(BS!B8-BS!B5-(BS!B26-BS!B23)+BS!B16))/2 -> 24765 | C15: =(C14+B14)/2 -> 44104.621 | D15: =(D14+C14)/2 -> 59555.217 | E15: =(E14+D14)/2 -> 70124.349 | F15: =(F14+E14)/2 -> 74853.415 | G15: =(G14+F14)/2 -> 75789.395
A16: ROIC % | B16: =IF(B15=0,0,B7/B15) -> -0.001784079 | C16: =IF(C15=0,0,C7/C15) -> 0.050108128 | D16: =IF(D15=0,0,D7/D15) -> 0.079757916 | E16: =IF(E15=0,0,E7/E15) -> 0.07764778 | F16: =IF(F15=0,0,F7/F15) -> 0.079034471 | G16: =IF(G15=0,0,G7/G15) -> 0.078441054
A18: RETURN ON EQUITY (ROE)
A19: NI Attr. to Common | B19: =IS!D37 -> -1167 | C19: =IS!E37 -> -254.8 | D19: =IS!F37 -> 2118.5 | E19: =IS!G37 -> 3222 | F19: =IS!H37 -> 4071.5 | G19: =IS!I37 -> 4329.6
A20: Avg Equity (excl NCI) | B20: =(BS!C42+BS!B42)/2 -> 2321.5 | C20: =(BS!D42+BS!C42)/2 -> 5107.6 | D20: =(BS!E42+BS!D42)/2 -> 10389.45 | E20: =(BS!F42+BS!E42)/2 -> 17009.7 | F20: =(BS!G42+BS!F42)/2 -> 23181.45 | G20: =(BS!H42+BS!G42)/2 -> 29207
A21: ROE % | B21: =IF(B20=0,0,B19/B20) -> -0.50269222 | C21: =IF(C20=0,0,C19/C20) -> -0.049886444 | D21: =IF(D20=0,0,D19/D20) -> 0.20390877 | E21: =IF(E20=0,0,E19/E20) -> 0.18942133 | F21: =IF(F20=0,0,F19/F20) -> 0.17563612 | G21: =IF(G20=0,0,G19/G20) -> 0.14823844
A23: RETURN ON ASSETS (ROA)
A24: Net Income | B24: =IS!D34 -> -1167 | C24: =IS!E34 -> -254.8 | D24: =IS!F34 -> 2118.5 | E24: =IS!G34 -> 3222 | F24: =IS!H34 -> 4071.5 | G24: =IS!I34 -> 4329.6
A25: Avg Total Assets | B25: =(BS!C18+BS!B18)/2 -> 33567.5 | C25: =(BS!D18+BS!C18)/2 -> 60357.538 | D25: =(BS!E18+BS!D18)/2 -> 77677.806 | E25: =(BS!F18+BS!E18)/2 -> 87224.563 | F25: =(BS!G18+BS!F18)/2 -> 92646.587 | G25: =(BS!H18+BS!G18)/2 -> 95410.699
A26: ROA % | B26: =IF(B25=0,0,B24/B25) -> -0.03476577 | C26: =IF(C25=0,0,C24/C25) -> -0.0042215108 | D26: =IF(D25=0,0,D24/D25) -> 0.027272912 | E26: =IF(E25=0,0,E24/E25) -> 0.036939136 | F26: =IF(F25=0,0,F24/F25) -> 0.043946573 | G26: =IF(G25=0,0,G24/G25) -> 0.045378559
A28: DUPONT DECOMPOSITION
A29: Net Profit Margin (NI/Rev) | B29: =IF(IS!D5=0,0,IS!D37/IS!D5) -> -0.22744104 | C29: =IF(IS!E5=0,0,IS!E37/IS!E5) -> -0.020384 | D29: =IF(IS!F5=0,0,IS!F37/IS!F5) -> 0.105925 | E29: =IF(IS!G5=0,0,IS!G37/IS!G5) -> 0.14645455 | F29: =IF(IS!H5=0,0,IS!H37/IS!H5) -> 0.16964583 | G29: =IF(IS!I5=0,0,IS!I37/IS!I5) -> 0.173184
A30: Asset Turnover (Rev/Avg TA) | B30: =IF(B25=0,0,IS!D5/B25) -> 0.15285619 | C30: =IF(C25=0,0,IS!E5/C25) -> 0.20709923 | D30: =IF(D25=0,0,IS!F5/D25) -> 0.2574738 | E30: =IF(E25=0,0,IS!G5/E25) -> 0.25222253 | F30: =IF(F25=0,0,IS!H5/F25) -> 0.25904894 | G30: =IF(G25=0,0,IS!I5/G25) -> 0.26202512
A31: Equity Multiplier (Avg TA/Avg Eq) | B31: =IF(B20=0,0,B25/B20) -> 14.459401 | C31: =IF(C20=0,0,C25/C20) -> 11.817201 | D31: =IF(D20=0,0,D25/D20) -> 7.4766043 | E31: =IF(E20=0,0,E25/E20) -> 5.1279307 | F31: =IF(F20=0,0,F25/F20) -> 3.9965829 | G31: =IF(G20=0,0,G25/G20) -> 3.2667066
A32: DuPont ROE Check (NPM×AT×EM) | B32: =B29*B30*B31 -> -0.50269222 | C32: =C29*C30*C31 -> -0.049886444 | D32: =D29*D30*D31 -> 0.20390877 | E32: =E29*E30*E31 -> 0.18942133 | F32: =F29*F30*F31 -> 0.17563612 | G32: =G29*G30*G31 -> 0.14823844
A33: DuPont vs ROE diff | B33: =B32-B21 -> 0 | C33: =C32-C21 -> 0 | D33: =D32-D21 -> 0 | E33: =E32-E21 -> 0 | F33: =F32-F21 -> 0 | G33: =G32-G21 -> 0
A35: ADDITIONAL METRICS
A36: Net Debt (Total Debt - Cash) | B36: =BS!C23+BS!C29-BS!C5 -> 17393 | C36: =BS!D23+BS!D29-BS!D5 -> 27239.042 | D36: =BS!E23+BS!E29-BS!E5 -> 30092.493 | E36: =BS!F23+BS!F29-BS!F5 -> 29136.805 | F36: =BS!G23+BS!G29-BS!G5 -> 24207.124 | G36: =BS!H23+BS!H29-BS!H5 -> 19457.666
A37: Net Debt / EBITDA | B37: =IF(IS!D43=0,0,B36/IS!D43) -> 5.7251481 | C37: =IF(IS!E43=0,0,C36/IS!E43) -> 3.6685579 | D37: =IF(IS!F43=0,0,D36/IS!F43) -> 2.5720079 | E37: =IF(IS!G43=0,0,E36/IS!G43) -> 2.1503177 | F37: =IF(IS!H43=0,0,F36/IS!H43) -> 1.6345121 | G37: =IF(IS!I43=0,0,G36/IS!I43) -> 1.2676004
A38: Interest Coverage (EBIT/Int Exp) | B38: =IF(IS!D27=0,0,IS!D22/(-IS!D27)) -> -0.037428804 | C38: =IF(IS!E27=0,0,IS!E22/(-IS!E27)) -> 0.88541667 | D38: =IF(IS!F27=0,0,IS!F22/(-IS!F27)) -> 1.7857143 | E38: =IF(IS!G27=0,0,IS!G22/(-IS!G27)) -> 2.42 | F38: =IF(IS!H27=0,0,IS!H22/(-IS!H27)) -> 3.1636364 | G38: =IF(IS!I27=0,0,IS!I22/(-IS!I27)) -> 3.625
A39: FCF (from CF) | B39: =CF!D38 -> -7251 | C39: =CF!E38 -> -10519.042 | D39: =CF!F38 -> -14053.45 | E39: =CF!G38 -> -5644.3128 | F39: =CF!H38 -> 1329.6813 | G39: =CF!I38 -> 3649.4582

Sheet Cross_Check
A1: CoreWeave, Inc. (CRWV) — Cross-Check & Assumption Validation
A2: Model validated against: 10-K filings, research memo, yfinance, management guidance
A3: Validation date: 2026-04-18
A5: SECTION 1: HISTORICAL DATA VALIDATION (Model vs yfinance / 10-K)
A6: Metric | B6: Period | C6: Model ($M) | D6: yfinance ($M) | E6: 10-K ($M) | F6: Diff % | G6: Match? | H6: Notes
A7: Revenue | B7: FY2023 | C7: 229 | D7: 229 | E7: 229 | F7: 0 | G7: Y | H7: MATCH - all sources agree
A8: Revenue | B8: FY2024 | C8: 1915 | D8: 1915 | E8: 1915 | F8: 0 | G8: Y | H8: MATCH - all sources agree
A9: Revenue | B9: FY2025 | C9: 5131 | D9: 5131 | E9: 5131 | F9: 0 | G9: Y | H9: MATCH - all sources agree
A10: Net Income | B10: FY2023 | C10: -594 | D10: -594 | E10: -594 | F10: 0 | G10: Y | H10: MATCH
A11: Net Income | B11: FY2024 | C11: -863 | D11: -863 | E11: -863 | F11: 0 | G11: Y | H11: MATCH
A12: Net Income | B12: FY2025 | C12: -1167 | D12: -1167 | E12: -1167 | F12: 0 | G12: Y | H12: MATCH
A13: Gross Profit | B13: FY2023 | C13: 160 | D13: 160 | E13: 160 | F13: 0 | G13: Y | H13: MATCH
A14: Gross Profit | B14: FY2024 | C14: 1422 | D14: 1422 | E14: 1422 | F14: 0 | G14: Y | H14: MATCH
A15: Gross Profit | B15: FY2025 | C15: 3678 | D15: 3678 | E15: 3678 | F15: 0 | G15: Y | H15: MATCH
A16: Total Assets | B16: FY2024 | C16: 17833 | D16: 17833 | E16: 17833 | F16: 0 | G16: Y | H16: MATCH
A17: Total Assets | B17: FY2025 | C17: 49302 | D17: 49302 | E17: 49302 | F17: 0 | G17: Y | H17: MATCH
A18: Total Debt | B18: FY2025 | C18: 29822 | D18: 29822 | E18: 29822 | F18: 0 | G18: Y | H18: MATCH - ST+LT debt
A19: Stockholders' Equity | B19: FY2025 | C19: 3335 | D19: 3335 | E19: 3335 | F19: 0 | G19: Y | H19: MATCH
A21: SECTION 2: FORECAST ASSUMPTION CROSS-CHECK
A22: # | B22: Cat | C22: Driver | D22: Model Value | E22: External Ref | F22: Source & Date | G22: Match? | H22: Severity | I22: Action
A23: 1 | B23: A | C23: FY2026E Revenue | D23: $12.5B | E23: $12-13B guidance | F23: CRWV FY2025 10-K, Feb 2026 | G23: Y | H23: L | I23: Note
A24: 2 | B24: A | C24: FY2026E Capex | D24: $20B | E24: $23-25B cash capex guidance | F24: 10-K/Earnings Call Q4'25 | G24: N | H24: H | I24: Monitor - model conservative on capex
A25: 3 | B25: A | C25: FY2026E Adj Op Income | D25: $2.75B | E25: $0.9-1.1B guidance | F25: 10-K FY2025 | G25: N | H25: H | I25: Model assumes higher margin; guidance includes ramp costs
A26: 4 | B26: A | C26: Active Power FY2026 | D26: >1.7GW | E26: >1.7GW guidance | F26: 10-K FY2025 | G26: Y | H26: L | I26: Note
A27: 5 | B27: B | C27: GPU Cloud Market Growth | D27: 40% CAGR | E27: 35-45% CAGR consensus | F27: IDC/Gartner 2025-2026 | G27: Y | H27: L | I27: Note
A28: 6 | B28: B | C28: Gross Margin FY2026E | D28: 70% | E28: 60-72% range (peers) | F28: NVDA/AMD/hyperscaler comps | G28: Y | H28: M | I28: Monitor - top-end; GPU price declines may compress
A29: 7 | B29: B | C29: GM Decline to 66% by FY2030 | D29: 66% | E29: 65-70% long-term range | F29: Industry consensus | G29: Y | H29: M | I29: Monitor
A30: 8 | B30: C | C30: Interest Expense FY2026E | D30: $2.5B | E30: $2.0-2.8B range | F30: Memo + validation doc | G30: Y | H30: M | I30: Within validated range
A31: 9 | B31: C | C31: Net Debt/EBITDA FY2026E | D31: ~2.5x | E31: 2-4x neocloud peer range | F31: S-1, credit analyst reports | G31: Y | H31: M | I31: Monitor deleverage path
A32: 10 | B32: A | C32: RPO (Remaining Perf Obligations) | D32: $60.7B | E32: $60.7B as of FY2025 | F32: 10-K FY2025 | G32: Y | H32: L | I32: Note - provides revenue visibility
A33: 11 | B33: A | C33: Backlog | D33: $87.8B | E33: $87.8B as of FY2025 | F33: 10-K FY2025 | G33: Y | H33: L | I33: Note - strong pipeline
A34: 12 | B34: B | C34: Revenue Deceleration FY27-30 | D34: 60%→10%→4% | E34: Typical hyperscaler maturation | F34: AMZN/MSFT/GOOG analogy | G34: Y | H34: M | I34: Reasonable deceleration curve
... A37: 15 | B37: A | C37: SBC FY2026E | D37: $1.0B | E37: Pre-IPO/post-IPO ramp | F37: S-1 prospectus | G37: Y | H37: M | I37: Post-IPO SBC typically elevated yr1-2
A39: SECTION 3: YFINANCE MAGNITUDE SANITY CHECK
A40: yfinance Rev FY2025 = $5,131M → Model = $5,131M → MATCH
A41: yfinance NI FY2025 = -$1,167M → Model = -$1,167M → MATCH
A42: yfinance EBITDA FY2025 = $2,468M → Model Adj EBITDA includes SBC add-back (higher) — acceptable diff
A43: yfinance TA FY2025 = $49,302M → Model = $49,302M → MATCH
A44: yfinance Total Debt FY2025 = $29,822M → Model (ST $8,175M + LT $21,647M = $29,822M) → MATCH
A45: yfinance Equity FY2025 = $3,335M → Model = $3,335M → MATCH
...

Sheet Scenarios
A1: CoreWeave, Inc. (CRWV) — Scenario Analysis & Sensitivity
A2: Probability-weighted valuation framework | Units: $M except per-share ($) | FY2027E target year
A4: SCENARIO PARAMETERS
A5: Scenario | B5: Prob. | C5: FY27E Rev ($M) | D5: EBITDA Margin | E5: FY27E EBITDA ($M) | F5: EV/EBITDA | G5: Implied EV ($M) | H5: Net Debt ($M) | I5: Mkt Cap ($M) | J5: Share Price ($)
A6: Bull | B6: 0.2 | C6: 25000 | D6: 0.6 | E6: =C6*D6 -> 15000 | F6: 15 | G6: =E6*F6 -> 225000 | H6: 33000 | I6: =MAX(0,G6-H6) -> 192000 | J6: =I6/Assumptions!C50 -> 336.84211
A7: Base | B7: 0.4 | C7: 20000 | D7: 0.55 | E7: =C7*D7 -> 11000 | F7: 12 | G7: =E7*F7 -> 132000 | H7: 35000 | I7: =MAX(0,G7-H7) -> 97000 | J7: =I7/Assumptions!C50 -> 170.17544
A8: Bear | B8: 0.25 | C8: 15000 | D8: 0.5 | E8: =C8*D8 -> 7500 | F8: 8 | G8: =E8*F8 -> 60000 | H8: 35000 | I8: =MAX(0,G8-H8) -> 25000 | J8: =I8/Assumptions!C50 -> 43.859649
A9: Distress | B9: 0.1 | C9: 10000 | D9: 0.4 | E9: =C9*D9 -> 4000 | F9: 5 | G9: =E9*F9 -> 20000 | H9: 35000 | I9: =MAX(0,G9-H9) -> 0 | J9: =I9/Assumptions!C50 -> 0
A11: PROBABILITY-WEIGHTED VALUATION
A12: Scenario | B12: Probability | C12: Share Price ($) | D12: Weighted ($)
A13: Bull | B13: =B6 -> 0.2 | C13: =J6 -> 336.84211 | D13: =B13*C13 -> 67.368421
A14: Base | B14: =B7 -> 0.4 | C14: =J7 -> 170.17544 | D14: =B14*C14 -> 68.070175
A15: Bear | B15: =B8 -> 0.25 | C15: =J8 -> 43.859649 | D15: =B15*C15 -> 10.964912
A16: Distress | B16: =B9 -> 0.1 | C16: =J9 -> 0 | D16: =B16*C16 -> 0
A17: Model Uncertainty | B17: 0.05 | D17: 0
A18: Probability-Weighted Target | B18: =SUM(B13:B17) -> 1 | D18: =SUM(D13:D17) -> 146.40351
A19: Current Share Price | C19: =Raw_Info!D109 -> 118.69
A20: Implied Upside / (Downside) | D20: =D18/C19-1 -> 0.23349489
A22: SENSITIVITY: IMPLIED SHARE PRICE ($)
A23: Net Debt = $35B fixed | Shares = 570M
A24: EBITDA ($M) ↓ \ Multiple → | B24: 8x | C24: 10x | D24: 12x | E24: 15x | F24: 18x
A25: 7500 | B25: 43.859649 | C25: 70.175439 | D25: 96.491228 | E25: 135.96491 | F25: 175.4386
A26: 10000 | B26: 78.947368 | C26: 114.03509 | D26: 149.12281 | E26: 201.75439 | F26: 254.38596
A27: 11000 | B27: 92.982456 | C27: 131.57895 | D27: 170.17544 | E27: 228.07018 | F27: 285.96491
A28: 13000 | B28: 121.05263 | C28: 166.66667 | D28: 212.2807 | E28: 280.70175 | F28: 349.12281
A29: 15000 | B29: 149.12281 | C29: 201.75439 | D29: 254.38596 | E29: 333.33333 | F29: 412.2807
A31: SENSITIVITY: NET DEBT IMPACT ON SHARE PRICE ($)
A32: EV/EBITDA = 12x fixed | Shares = 570M
A33: EBITDA ($M) ↓ \ Net Debt ($M) → | B33: $30B | C33: $33B | D33: $35B | E33: $38B | F33: $40B
A34: 7500 | B34: 105.26316 | C34: 100 | D34: 96.491228 | E34: 91.22807 | F34: 87.719298
A35: 10000 | B35: 157.89474 | C35: 152.63158 | D35: 149.12281 | E35: 143.85965 | F35: 140.35088
A36: 11000 | B36: 178.94737 | C36: 173.68421 | D36: 170.17544 | E36: 164.91228 | F36: 161.40351
A37: 13000 | B37: 221.05263 | C37: 215.78947 | D37: 212.2807 | E37: 207.01754 | F37: 203.50877
A38: 15000 | B38: 263.15789 | C38: 257.89474 | D38: 254.38596 | E38: 249.12281 | F38: 245.61404
A40: SCENARIO FRAMEWORK MATRIX
C41: GPU Price Holds Firm | D41: GPU Price Drops Sharply
A42: Customer | B42: Demand Strong | C42: Bull | D42: Base
A43: Customer | B43: Demand Slowing | C43: Base | D43: Bear
A44: Customer | B44: Demand Contracting | C44: Bear | D44: Distress
A45: Third dimension: Financing environment (loose/tight) → shifts scenarios down/up
...

Sheet Raw_Info
A1: CoreWeave, Inc. (CRWV) — Raw Financial Data
A2: US GAAP | Units: $M | Data Confidence: HIGH | Sources: NLM (10-K) + Research Memo
A3: Line Item | B3: FY2023 | C3: FY2024 | D3: FY2025 | E3: Notes / Source
A4: INCOME STATEMENT
A5: IS: Revenue (Total) | B5: 229 | C5: 1915 | D5: 5131 | E5: [NLM 10-K ✅] Memo $5,130M match
A6: IS: Cost of Revenue | B6: 69 | C6: 493 | D6: 1453 | E6: [NLM 10-K ✅]
A7: IS: Gross Profit | B7: 160 | C7: 1422 | D7: 3678 | E7: [NLM calc: Rev - COGS]
A8: IS: Technology & Infrastructure | B8: 132 | C8: 961 | D8: 2929 | E8: [NLM 10-K] incl R&D
A9: IS: Sales & Marketing | B9: 13 | C9: 18 | D9: 144 | E9: [NLM 10-K]
A10: IS: General & Administrative | B10: 30 | C10: 119 | D10: 651 | E10: [NLM 10-K]
A11: IS: Total Operating Expenses | B11: 243 | C11: 1591 | D11: 5177 | E11: [NLM 10-K] incl COGS
A12: IS: Operating Income (Loss) | B12: -14 | C12: 324 | D12: -46 | E12: [NLM 10-K]
A13: IS: Fair Value Adj Gain/(Loss) | B13: -534 | C13: -756 | D13: 27 | E13: [NLM 10-K] warrant/derivative
A14: IS: Interest Expense, net | B14: -28 | C14: -361 | D14: -1229 | E14: [NLM 10-K ✅] Memo $1,229M match
A15: IS: Other Income, net | B15: 19 | C15: 49 | D15: 33 | E15: [NLM 10-K]
A16: IS: Loss Before Tax | B16: -558 | C16: -744 | D16: -1215 | E16: [NLM 10-K]
... A21: IS: R&D (embedded in Tech&Infra) | B21: 21 | C21: 56 | D21: 352 | E21: [NLM 10-K]
A22: IS: Adj. EBITDA | D22: 3090 | E22: [Memo] 60.2% margin FY2025
A24: QUARTERLY REVENUE (FY2025)
A25: IS: Q1 2025 Revenue | D25: 982 | E25: [Memo] $981.6M
A26: IS: Q2 2025 Revenue | D26: 1213 | E26: [Memo] +24% QoQ
A27: IS: Q3 2025 Revenue | D27: 1365 | E27: [Memo] +13% QoQ
A28: IS: Q4 2025 Revenue | D28: 1572 | E28: [Memo] +15% QoQ
A30: BALANCE SHEET
A31: BS: Cash & Equivalents | C31: 1398 | D31: 3980 | E31: [NLM 10-K ✅]
A32: BS: Accounts Receivable, net | C32: 417 | D32: 3169 | E32: [NLM 10-K]
A33: BS: Prepaid & Other Current | C33: 101 | D33: 339 | E33: [NLM 10-K]
A34: BS: Total Current Assets | C34: 1916 | D34: 7488 | E34: [NLM 10-K]
A35: BS: PP&E, net | C35: 11915 | D35: 30557 | E35: [NLM 10-K]
A36: BS: Intangible Assets, net | C36: 5 | D36: 235 | E36: [NLM 10-K]
A37: BS: Goodwill | C37: 20 | D37: 1101 | E37: [NLM 10-K] W&B acquisition
A38: BS: ROU Assets (Operating Lease) | C38: 2590 | D38: 8231 | E38: [NLM 10-K]
A39: BS: Other Non-Current Assets | C39: 1387 | D39: 1690 | E39: [NLM 10-K]
A40: BS: Total Non-Current Assets | C40: 15917 | D40: 41814 | E40: [NLM 10-K]
A41: BS: Total Assets | C41: 17833 | D41: 49302 | E41: [NLM 10-K]
A42: BS: Accounts Payable | C42: 868 | D42: 1623 | E42: [NLM 10-K]
... A59: BS: Total Liab + Mezzanine + Equity | C59: 17833 | D59: 49302 | E59: [NLM 10-K] = Total Assets ✅
A61: CASH FLOW STATEMENT
A62: CF: Net Income (Loss) | B62: -594 | C62: -863 | D62: -1167 | E62: [NLM 10-K]
A63: CF: D&A | B63: 103 | C63: 863 | D63: 2454 | E63: [NLM 10-K]
...

Sheet _State
A1: SKILL_VERSION: 4.8
A2: DATA_SOURCES: [MEMO, NLM]
A3: DATA_CONFIDENCE: HIGH
A4: IS_GRANULARITY: Annual
A5: CF_GRANULARITY: Annual
A6: BS_GRANULARITY: Annual
A7: HIST_YEARS: ["FY2023", "FY2024", "FY2025"]
A8: FCST_YEARS: ["FY2026E", "FY2027E", "FY2028E", "FY2029E", "FY2030E"]
A9: UNIT: $M
A10: GAAP: US GAAP
A11: COMPANY: CoreWeave, Inc.
A12: TICKER: CRWV
... A34: MODEL_COMPLETE: TRUE
